Workbook

Sheet Lies_mich
A1: Referenzdaten für Docking und Vergleich: Cohen, March und Olsen (1972) sowie Fioretti und Lomi (2008)
A2: Stand 16.10.2026. Extrahiert aus den Projekt-PDFs; alle Tabellenwerte am Scan geprüft, Abbildungswerte digitalisiert.
A4: Quellen
A5: Kürzel | B5: Angabe | C5: Verwendete Teile
A6: CMO 1972 | B6: Cohen, Michael D.; March, James G.; Olsen, Johan P. (1972): A Garbage Can Model of Organizational Choice. Administrative Science Quarterly 17 (1), S. 1 bis 25. DOI 10.2307/2392088. | C6: Tabellen 1 bis 5, Zahlen im Text, Parameter S. 4 bis 8, Kennzahlen S. 8, 9, 17, 18, Listing S. 19 bis 24
A7: FL 2008 | B7: Fioretti, Guido; Lomi, Alessandro (2008): An Agent-Based Representation of the Garbage Can Model of Organizational Choice. Journal of Artificial Societies and Social Simulation 11 (1), 1. http://jasss.soc.surrey.ac.uk/11/1/1.html | C7: Abs. 3 bis 7, Gleichungen 5 bis 8, Abb. 12 bis 19
A8: Fioretti aktuell | B8: Fioretti, Guido: GarbageCan_simplified17.nlogox (NetLogo 7.0.4), Info-Tab; unveröffentlichte Version, bei Open ABM eingereicht. Verweist auf Fioretti, Guido (2024): Emergence and Evolution of Organizations out of Garbage Can Dynamics. Industrial and Corporate Change 33 (4), S. 808 bis 830. | C8: Nur qualitative Eigenschaften und Versuchsplan
A10: Fundstellen
B11: CMO: Seitenzahlen der Zeitschrift. Im JSTOR-PDF ist die PDF-Seite gleich Zeitschriftenseite plus 1 (Deckblatt). FL: Absatznummern (Abs.) und Abbildungsnummern der JASSS-Fassung, die keine Seitenzahlen hat.
A13: Werttypen und Farben
A14: blaue Schrift | B14: Wert aus der Quelle übernommen (Tabelle, Text, Datenkarte) oder Eingabewert.
A15: schwarze Schrift | B15: Formel im selben Blatt.
A16: grüne Schrift | B16: Formel mit Verweis auf ein anderes Blatt.
A17: orange Füllung | B17: Aus einer Abbildung digitalisiert; Unsicherheit in der jeweiligen Spalte bzw. Kommentar.
A18: hellgrüne Füllung | B18: Berechnete Prüf- oder Hilfsgröße.
A19: gelbe Füllung | B19: Zum Ausfüllen gedacht (eigene Werte, Toleranzen, Ergebnisse).
A20: Kommentar (rotes Dreieck) | B20: Annotation an der Zelle mit Hinweisen zu Auffälligkeiten oder Lesarten.
A22: Werttyp in Daten_long
A23: publiziert (Tabelle) | B23: Wert wie in einer Tabelle gedruckt.
A24: publiziert (Text) | B24: Wert im Fließtext genannt.
A25: digitalisiert | B25: Pixelgenau aus einer Abbildung abgelesen; nur für Rangfolgen, Richtungen und Größenordnungen geeignet.
A26: Normierung | B26: Festgelegter Bezugswert einer Indexdarstellung (100).
A28: Blätter
A29: CMO_Design | B29: Feste Parameter, Lastniveaus, Versuchsplan, Konventionen.
A30: CMO_Strukturen | B30: Matrizen A0 bis A2 und D0 bis D2, Energieverteilungen, Eintrittsfolgen und daraus berechnete Eintrittsperioden mit Abgleich gegen die Datenkarten.
A31: CMO_Kennzahlen | B31: Zehn Kennzahlen des Fortran-Programms mit Zählweise laut Listing und Verwendung in den Tabellen.
A32: CMO_Tab1 bis CMO_Tab5 | B32: Tabellen 1 bis 5 im Layout des Artikels mit Rand- und Prüfrechnungen.
A33: CMO_Textwerte | B33: Zahlen aus dem Fließtext und Nachrechnung der Aussagen zu Tab. 5.
A34: CMO_Eigenschaften | B34: Acht Eigenschaften als relationale Docking-Ziele mit Status bei FL und Operationalisierungsvorschlag.
A35: FL_Design, FL_Kennzahlen | B35: Basiswerte, Versuchsaufbau je Abbildung, Übersetzung der Kennzahlen.
A36: FL_Abb12_13_18, FL_Abb14, FL_Abb15_17, FL_Abb19 | B36: Digitalisierte und im Text genannte Ergebnisse.
A37: FL_Befunde | B37: Bestätigte und nicht bestätigte CMO-Aussagen, Einzelbefunde.
A38: Fioretti_aktuell | B38: Eigenschaften und Versuchsplan des aktuellen NetLogo-Modells sowie Hinweise für den Port.
A39: Pruefungen | B39: Automatische Konsistenzprüfungen und Protokoll des Scanabgleichs.
A40: Docking_CMO | B40: Vorlage für den Zahlenvergleich mit eigenem Port: Toleranzen, eigene Werte, Status.
A41: Daten_long | B41: Alle Zahlen in einer Tabelle; identisch mit der CSV-Datei.
A43: Hinweise zur Nutzung
B44: Die Tabellen 1 bis 4 von CMO sind Mittelwerte über die vier Kombinationen der Eintrittsfolgen. Die Zahl der Läufe je Zelle ist aus dem Versuchsplan abgeleitet und in der Spalte aggregation vermerkt.
B45: Das Fortran-Programm gibt keine Entscheidungsstile aus. Sie müssen aus den Verläufen (IO = 2) nach der Definition auf S. 8 bestimmt werden; Mischfälle aus Flight und Resolution zählen als Resolution.
B46: Die CMO-Werte sind gerundet gedruckt. Die Rundungstoleranz beträgt eine halbe Einheit der letzten gedruckten Stelle (Blatt Docking_CMO).
...

Sheet CMO_Design
A1: Cohen, March und Olsen (1972): Simulationsdesign und feste Parameter
A2: Seitenangaben beziehen sich auf die Zeitschriftenpaginierung (ASQ 17, 1972). Blaue Werte sind aus dem Artikel übernommen, schwarze sind Formeln.
A4: Parameter | B4: Wert | C4: Einheit oder Kodierung | D4: Fundstelle | E4: Anmerkung
A5: Zeitperioden | B5: 20 | C5: Perioden | D5: S. 4
A6: Entscheidungsgelegenheiten (choices, m) | B6: 10 | C6: Anzahl | D6: S. 4 | E6: Eine Gelegenheit tritt je Periode in den ersten zehn Perioden ein (S. 5).
A7: Entscheidungsträger (decision makers, v) | B7: 10 | C7: Anzahl | D7: S. 4 | E7: Im Programm stehen alle Entscheidungsträger ab Periode 1 zur Verfügung (vgl. Fioretti und Lomi 2008, Abs. 3.2).
A8: Probleme (w) | B8: 20 | C8: Anzahl | D8: S. 4 | E8: Zwei Probleme treten je Periode in den ersten zehn Perioden ein (S. 5).
A9: Lösungskoeffizient je Periode | B9: 0.6 | C9: Faktor auf die Energie | D9: S. 4 und 5 | E9: Für alle berichteten Ergebnisse konstant 0,6. Fußnote 3 nennt eine zeitlich variierende Reihe als Robustheitsprüfung (siehe unten).
A10: Energie aller Entscheidungsträger je Periode | B10: 5.5 | C10: Energieeinheiten | D10: S. 5 und 7 | E10: Gilt für alle drei Energieverteilungen E0, E1, E2.
A11: Gesamtenergie über alle Perioden | B11: =B10*B5 -> 110 | C11: Energieeinheiten | D11: S. 5 | E11: Im Artikel 110.
A12: Effektive Gesamtenergie (nach Lösungskoeffizient) | B12: =B11*B9 -> 66 | C12: Energieeinheiten | D12: S. 5 | E12: Im Artikel 66.
A13: Energiebedarf je Problem, Last 0 (leicht, light load) | B13: 1.1 | C13: Energieeinheiten | D13: S. 5 | E13: Im Fortran-Listing XERP(J) = IL * 1,1 mit IL = 1; ausgegeben wird LOAD = IL minus 1 = 0.
A14: Mindestbedarf aller Probleme, Last 0 | B14: =B8*B13 -> 22 | C14: Energieeinheiten | D14: S. 5
A15: Nettolast, Last 0 (Formel) | B15: =B14-B12 -> -44 | C15: Energieeinheiten | D15: S. 5 | E15: Im Artikel -44. Negative Werte bedeuten, dass rechnerisch genug Energie vorhanden ist.
A16: Nettolast, Last 0 (gedruckter Wert) | B16: -44 | C16: Energieeinheiten | D16: S. 5
A17: Energiebedarf je Problem, Last 1 (mittel, moderate load) | B17: 2.2 | C17: Energieeinheiten | D17: S. 5 | E17: Im Fortran-Listing XERP(J) = IL * 1,1 mit IL = 2; ausgegeben wird LOAD = IL minus 1 = 1.
A18: Mindestbedarf aller Probleme, Last 1 | B18: =B8*B17 -> 44 | C18: Energieeinheiten | D18: S. 5
A19: Nettolast, Last 1 (Formel) | B19: =B18-B12 -> -22 | C19: Energieeinheiten | D19: S. 5 | E19: Im Artikel -22. Negative Werte bedeuten, dass rechnerisch genug Energie vorhanden ist.
A20: Nettolast, Last 1 (gedruckter Wert) | B20: -22 | C20: Energieeinheiten | D20: S. 5
A21: Energiebedarf je Problem, Last 2 (schwer, heavy load) | B21: 3.3 | C21: Energieeinheiten | D21: S. 5 | E21: Im Fortran-Listing XERP(J) = IL * 1,1 mit IL = 3; ausgegeben wird LOAD = IL minus 1 = 2.
A22: Mindestbedarf aller Probleme, Last 2 | B22: =B8*B21 -> 66 | C22: Energieeinheiten | D22: S. 5
A23: Nettolast, Last 2 (Formel) | B23: =B22-B12 -> 0 | C23: Energieeinheiten | D23: S. 5 | E23: Im Artikel 0. Negative Werte bedeuten, dass rechnerisch genug Energie vorhanden ist.
A24: Nettolast, Last 2 (gedruckter Wert) | B24: 0 | C24: Energieeinheiten | D24: S. 5
A25: Zugangsstrukturen (access structure, Matrix A) | B25: 0, 1, 2 | C25: 0 unsegmentiert, 1 hierarchisch, 2 spezialisiert | D25: S. 5 und 6 | E25: Probleme zu Gelegenheiten. Matrizen im Blatt CMO_Strukturen.
A26: Entscheidungsstrukturen (decision structure, Matrix D) | B26: 0, 1, 2 | C26: 0 unsegmentiert, 1 hierarchisch, 2 spezialisiert | D26: S. 6 und 7 | E26: Entscheidungsträger zu Gelegenheiten. Das Fortran-Programm speichert D transponiert als IKA(Gelegenheit, Entscheidungsträger).
A27: Energieverteilungen | B27: 0, 1, 2 | C27: 0 Wichtige haben weniger Energie, 1 gleiche Energie, 2 Wichtige haben mehr Energie | D27: S. 7 | E27: Wichtigkeit gilt über die Nummer des Entscheidungsträgers auch bei unsegmentierter oder spezialisierter Struktur (S. 7 und 8).
A28: Organisationstypen (Formel 3 hoch 4) | B28: =3^4 -> 81 | C28: Anzahl | D28: S. 8 | E28: Last, Zugang, Entscheidungsstruktur, Energieverteilung mit je drei Ausprägungen.
A29: Kombinationen der Eintrittsfolgen | B29: 4 | C29: Anzahl | D29: S. 5 und 8 | E29: Zwei Folgen für Gelegenheiten mal zwei Folgen für Probleme; im Artikel nicht benannt, hier (a) und (b) wie auf S. 5.
A30: Simulationssituationen (Formel) | B30: =B28*B29 -> 324 | C30: Läufe | D30: S. 8 | E30: Im Artikel 324. Das Modell ist deterministisch, jede Situation ist genau ein Lauf.
A31: Bewegungsbedingung NA | B31: 1 | C31: Kodierung im Listing | D31: S. 17 und 19 | E31: Alle Ergebnisse beruhen auf NA = 1 (Probleme und Entscheidungsträger bewegen sich). NA = 2 bis 4 sind im Listing vorgesehen, aber nicht berichtet.
A32: Ausgabesteuerung IO | B32: 1 oder 2 | C32: Kodierung im Listing | D32: S. 17 und 19 | E32: IO = 1 druckt nur die zehn Kennzahlen, IO = 2 zusätzlich die Verläufe. Entscheidungsstile lassen sich nur aus den Verläufen bestimmen.
A33: Anfangswert Energiebedarf einer Gelegenheit XERC(I) | B33: 1.1 | C33: Energieeinheiten | D33: Listing S. 20 | E33: Wird vor Periode 1 gesetzt. Er wirkt auf die Bewertung einer Gelegenheit in ihrer Eintrittsperiode, bevor ihr Bedarf erstmals aus angehängten Problemen berechnet wird. Für Ports als expliziter Parameter sinnvoll.
A34: Variierende Lösungskoeffizienten (Fußnote 3) | B34: 1; 0,9; 0,7; 0,3; 0,1; 0,1; 0,3; 0,7; 0,9; 1; danach 10 mal 0,6 | C34: Faktor je Periode 1 bis 20 | D34: S. 5, Fn. 3 | E34: Nur mit einer Kombination der Eintrittsfolgen gerechnet; laut Artikel mit allen Schlussfolgerungen konsistent, ohne Zahlen. Die im Anhang gedruckten Datenkarten (S. 24) enthalten genau diese Reihe und nicht die konstante 0,6.
A35: Zuordnung der Entscheidungsstile | B35: Konvention | C35: Resolution, Oversight, Flight | D35: S. 8 | E35: Entscheidungen, bei denen ein Teil der Probleme abwandert und der Rest gelöst wird, zählen als Resolution. Die drei Stile sind je Entscheidung disjunkt und erschöpfend; Bezugsgröße sind die getroffenen Entscheidungen.

Sheet CMO_Strukturen
A1: Cohen, March und Olsen (1972): Strukturmatrizen, Energieverteilungen und Eintrittsfolgen
A2: Matrizen per Formel aus den Regeln erzeugt; sie entsprechen dem Druckbild S. 5 bis 7. Zeile = Problem i bzw. Entscheidungsträger i, Spalte = Gelegenheit j, 1 = zulässig.
A3: Regeln: A1 zulässig, wenn j größer oder gleich aufgerundet(i/2); A2 zulässig, wenn j gleich aufgerundet(i/2); D1 zulässig, wenn j größer oder gleich i; D2 zulässig, wenn j gleich i. Niedrige Nummern bedeuten hohe Wichtigkeit.
A5: Zugangsstrukturen (Probleme x Gelegenheiten)
B6: A0 unsegmentiert | N6: A1 hierarchisch | Z6: A2 spezialisiert
B7: i \ j | C7: 1 | D7: 2 | E7: 3 | F7: 4 | G7: 5 | H7: 6 | I7: 7 | J7: 8 | K7: 9 | L7: 10 | N7: i \ j | O7: 1 | P7: 2 | Q7: 3 | R7: 4 | S7: 5 | T7: 6 | U7: 7 | V7: 8 | W7: 9 | X7: 10 | Z7: i \ j | AA7: 1 | AB7: 2 | AC7: 3 | AD7: 4 | AE7: 5 | AF7: 6 | AG7: 7 | AH7: 8 | AI7: 9 | AJ7: 10
B8: 1 | C8: =1 -> 1 | D8: =1 -> 1 | E8: =1 -> 1 | F8: =1 -> 1 | G8: =1 -> 1 | H8: =1 -> 1 | I8: =1 -> 1 | J8: =1 -> 1 | ... L8: =1 -> 1 | N8: 1 | O8: =IF(O$7>=ROUNDUP($N8/2,0),1,0) -> 1 | P8: =IF(P$7>=ROUNDUP($N8/2,0),1,0) -> 1 | Q8: =IF(Q$7>=ROUNDUP($N8/2,0),1,0) -> 1 | R8: =IF(R$7>=ROUNDUP($N8/2,0),1,0) -> 1 | S8: =IF(S$7>=ROUNDUP($N8/2,0),1,0) -> 1 | T8: =IF(T$7>=ROUNDUP($N8/2,0),1,0) -> 1 | U8: =IF(U$7>=ROUNDUP($N8/2,0),1,0) -> 1 | V8: =IF(V$7>=ROUNDUP($N8/2,0),1,0) -> 1 | ... X8: =IF(X$7>=ROUNDUP($N8/2,0),1,0) -> 1 | Z8: 1 | AA8: =IF(AA$7=ROUNDUP($Z8/2,0),1,0) -> 1 | AB8: =IF(AB$7=ROUNDUP($Z8/2,0),1,0) -> 0 | AC8: =IF(AC$7=ROUNDUP($Z8/2,0),1,0) -> 0 | AD8: =IF(AD$7=ROUNDUP($Z8/2,0),1,0) -> 0 | AE8: =IF(AE$7=ROUNDUP($Z8/2,0),1,0) -> 0 | AF8: =IF(AF$7=ROUNDUP($Z8/2,0),1,0) -> 0 | AG8: =IF(AG$7=ROUNDUP($Z8/2,0),1,0) -> 0 | AH8: =IF(AH$7=ROUNDUP($Z8/2,0),1,0) -> 0 | ... AJ8: =IF(AJ$7=ROUNDUP($Z8/2,0),1,0) -> 0
B9: 2 | C9: =1 -> 1 | D9: =1 -> 1 | E9: =1 -> 1 | F9: =1 -> 1 | G9: =1 -> 1 | H9: =1 -> 1 | I9: =1 -> 1 | J9: =1 -> 1 | ... L9: =1 -> 1 | N9: 2 | O9: =IF(O$7>=ROUNDUP($N9/2,0),1,0) -> 1 | P9: =IF(P$7>=ROUNDUP($N9/2,0),1,0) -> 1 | Q9: =IF(Q$7>=ROUNDUP($N9/2,0),1,0) -> 1 | R9: =IF(R$7>=ROUNDUP($N9/2,0),1,0) -> 1 | S9: =IF(S$7>=ROUNDUP($N9/2,0),1,0) -> 1 | T9: =IF(T$7>=ROUNDUP($N9/2,0),1,0) -> 1 | U9: =IF(U$7>=ROUNDUP($N9/2,0),1,0) -> 1 | V9: =IF(V$7>=ROUNDUP($N9/2,0),1,0) -> 1 | ... X9: =IF(X$7>=ROUNDUP($N9/2,0),1,0) -> 1 | Z9: 2 | AA9: =IF(AA$7=ROUNDUP($Z9/2,0),1,0) -> 1 | AB9: =IF(AB$7=ROUNDUP($Z9/2,0),1,0) -> 0 | AC9: =IF(AC$7=ROUNDUP($Z9/2,0),1,0) -> 0 | AD9: =IF(AD$7=ROUNDUP($Z9/2,0),1,0) -> 0 | AE9: =IF(AE$7=ROUNDUP($Z9/2,0),1,0) -> 0 | AF9: =IF(AF$7=ROUNDUP($Z9/2,0),1,0) -> 0 | AG9: =IF(AG$7=ROUNDUP($Z9/2,0),1,0) -> 0 | AH9: =IF(AH$7=ROUNDUP($Z9/2,0),1,0) -> 0 | ... AJ9: =IF(AJ$7=ROUNDUP($Z9/2,0),1,0) -> 0
B10: 3 | C10: =1 -> 1 | D10: =1 -> 1 | E10: =1 -> 1 | F10: =1 -> 1 | G10: =1 -> 1 | H10: =1 -> 1 | I10: =1 -> 1 | J10: =1 -> 1 | ... L10: =1 -> 1 | N10: 3 | O10: =IF(O$7>=ROUNDUP($N10/2,0),1,0) -> 0 | P10: =IF(P$7>=ROUNDUP($N10/2,0),1,0) -> 1 | Q10: =IF(Q$7>=ROUNDUP($N10/2,0),1,0) -> 1 | R10: =IF(R$7>=ROUNDUP($N10/2,0),1,0) -> 1 | S10: =IF(S$7>=ROUNDUP($N10/2,0),1,0) -> 1 | T10: =IF(T$7>=ROUNDUP($N10/2,0),1,0) -> 1 | U10: =IF(U$7>=ROUNDUP($N10/2,0),1,0) -> 1 | V10: =IF(V$7>=ROUNDUP($N10/2,0),1,0) -> 1 | ... X10: =IF(X$7>=ROUNDUP($N10/2,0),1,0) -> 1 | Z10: 3 | AA10: =IF(AA$7=ROUNDUP($Z10/2,0),1,0) -> 0 | AB10: =IF(AB$7=ROUNDUP($Z10/2,0),1,0) -> 1 | AC10: =IF(AC$7=ROUNDUP($Z10/2,0),1,0) -> 0 | AD10: =IF(AD$7=ROUNDUP($Z10/2,0),1,0) -> 0 | AE10: =IF(AE$7=ROUNDUP($Z10/2,0),1,0) -> 0 | AF10: =IF(AF$7=ROUNDUP($Z10/2,0),1,0) -> 0 | AG10: =IF(AG$7=ROUNDUP($Z10/2,0),1,0) -> 0 | AH10: =IF(AH$7=ROUNDUP($Z10/2,0),1,0) -> 0 | ... AJ10: =IF(AJ$7=ROUNDUP($Z10/2,0),1,0) -> 0
B11: 4 | C11: =1 -> 1 | D11: =1 -> 1 | E11: =1 -> 1 | F11: =1 -> 1 | G11: =1 -> 1 | H11: =1 -> 1 | I11: =1 -> 1 | J11: =1 -> 1 | ... L11: =1 -> 1 | N11: 4 | O11: =IF(O$7>=ROUNDUP($N11/2,0),1,0) -> 0 | P11: =IF(P$7>=ROUNDUP($N11/2,0),1,0) -> 1 | Q11: =IF(Q$7>=ROUNDUP($N11/2,0),1,0) -> 1 | R11: =IF(R$7>=ROUNDUP($N11/2,0),1,0) -> 1 | S11: =IF(S$7>=ROUNDUP($N11/2,0),1,0) -> 1 | T11: =IF(T$7>=ROUNDUP($N11/2,0),1,0) -> 1 | U11: =IF(U$7>=ROUNDUP($N11/2,0),1,0) -> 1 | V11: =IF(V$7>=ROUNDUP($N11/2,0),1,0) -> 1 | ... X11: =IF(X$7>=ROUNDUP($N11/2,0),1,0) -> 1 | Z11: 4 | AA11: =IF(AA$7=ROUNDUP($Z11/2,0),1,0) -> 0 | AB11: =IF(AB$7=ROUNDUP($Z11/2,0),1,0) -> 1 | AC11: =IF(AC$7=ROUNDUP($Z11/2,0),1,0) -> 0 | AD11: =IF(AD$7=ROUNDUP($Z11/2,0),1,0) -> 0 | AE11: =IF(AE$7=ROUNDUP($Z11/2,0),1,0) -> 0 | AF11: =IF(AF$7=ROUNDUP($Z11/2,0),1,0) -> 0 | AG11: =IF(AG$7=ROUNDUP($Z11/2,0),1,0) -> 0 | AH11: =IF(AH$7=ROUNDUP($Z11/2,0),1,0) -> 0 | ... AJ11: =IF(AJ$7=ROUNDUP($Z11/2,0),1,0) -> 0
B12: 5 | C12: =1 -> 1 | D12: =1 -> 1 | E12: =1 -> 1 | F12: =1 -> 1 | G12: =1 -> 1 | H12: =1 -> 1 | I12: =1 -> 1 | J12: =1 -> 1 | ... L12: =1 -> 1 | N12: 5 | O12: =IF(O$7>=ROUNDUP($N12/2,0),1,0) -> 0 | P12: =IF(P$7>=ROUNDUP($N12/2,0),1,0) -> 0 | Q12: =IF(Q$7>=ROUNDUP($N12/2,0),1,0) -> 1 | R12: =IF(R$7>=ROUNDUP($N12/2,0),1,0) -> 1 | S12: =IF(S$7>=ROUNDUP($N12/2,0),1,0) -> 1 | T12: =IF(T$7>=ROUNDUP($N12/2,0),1,0) -> 1 | U12: =IF(U$7>=ROUNDUP($N12/2,0),1,0) -> 1 | V12: =IF(V$7>=ROUNDUP($N12/2,0),1,0) -> 1 | ... X12: =IF(X$7>=ROUNDUP($N12/2,0),1,0) -> 1 | Z12: 5 | AA12: =IF(AA$7=ROUNDUP($Z12/2,0),1,0) -> 0 | AB12: =IF(AB$7=ROUNDUP($Z12/2,0),1,0) -> 0 | AC12: =IF(AC$7=ROUNDUP($Z12/2,0),1,0) -> 1 | AD12: =IF(AD$7=ROUNDUP($Z12/2,0),1,0) -> 0 | AE12: =IF(AE$7=ROUNDUP($Z12/2,0),1,0) -> 0 | AF12: =IF(AF$7=ROUNDUP($Z12/2,0),1,0) -> 0 | AG12: =IF(AG$7=ROUNDUP($Z12/2,0),1,0) -> 0 | AH12: =IF(AH$7=ROUNDUP($Z12/2,0),1,0) -> 0 | ... AJ12: =IF(AJ$7=ROUNDUP($Z12/2,0),1,0) -> 0
B13: 6 | C13: =1 -> 1 | D13: =1 -> 1 | E13: =1 -> 1 | F13: =1 -> 1 | G13: =1 -> 1 | H13: =1 -> 1 | I13: =1 -> 1 | J13: =1 -> 1 | ... L13: =1 -> 1 | N13: 6 | O13: =IF(O$7>=ROUNDUP($N13/2,0),1,0) -> 0 | P13: =IF(P$7>=ROUNDUP($N13/2,0),1,0) -> 0 | Q13: =IF(Q$7>=ROUNDUP($N13/2,0),1,0) -> 1 | R13: =IF(R$7>=ROUNDUP($N13/2,0),1,0) -> 1 | S13: =IF(S$7>=ROUNDUP($N13/2,0),1,0) -> 1 | T13: =IF(T$7>=ROUNDUP($N13/2,0),1,0) -> 1 | U13: =IF(U$7>=ROUNDUP($N13/2,0),1,0) -> 1 | V13: =IF(V$7>=ROUNDUP($N13/2,0),1,0) -> 1 | ... X13: =IF(X$7>=ROUNDUP($N13/2,0),1,0) -> 1 | Z13: 6 | AA13: =IF(AA$7=ROUNDUP($Z13/2,0),1,0) -> 0 | AB13: =IF(AB$7=ROUNDUP($Z13/2,0),1,0) -> 0 | AC13: =IF(AC$7=ROUNDUP($Z13/2,0),1,0) -> 1 | AD13: =IF(AD$7=ROUNDUP($Z13/2,0),1,0) -> 0 | AE13: =IF(AE$7=ROUNDUP($Z13/2,0),1,0) -> 0 | AF13: =IF(AF$7=ROUNDUP($Z13/2,0),1,0) -> 0 | AG13: =IF(AG$7=ROUNDUP($Z13/2,0),1,0) -> 0 | AH13: =IF(AH$7=ROUNDUP($Z13/2,0),1,0) -> 0 | ... AJ13: =IF(AJ$7=ROUNDUP($Z13/2,0),1,0) -> 0
B14: 7 | C14: =1 -> 1 | D14: =1 -> 1 | E14: =1 -> 1 | F14: =1 -> 1 | G14: =1 -> 1 | H14: =1 -> 1 | I14: =1 -> 1 | J14: =1 -> 1 | ... L14: =1 -> 1 | N14: 7 | O14: =IF(O$7>=ROUNDUP($N14/2,0),1,0) -> 0 | P14: =IF(P$7>=ROUNDUP($N14/2,0),1,0) -> 0 | Q14: =IF(Q$7>=ROUNDUP($N14/2,0),1,0) -> 0 | R14: =IF(R$7>=ROUNDUP($N14/2,0),1,0) -> 1 | S14: =IF(S$7>=ROUNDUP($N14/2,0),1,0) -> 1 | T14: =IF(T$7>=ROUNDUP($N14/2,0),1,0) -> 1 | U14: =IF(U$7>=ROUNDUP($N14/2,0),1,0) -> 1 | V14: =IF(V$7>=ROUNDUP($N14/2,0),1,0) -> 1 | ... X14: =IF(X$7>=ROUNDUP($N14/2,0),1,0) -> 1 | Z14: 7 | AA14: =IF(AA$7=ROUNDUP($Z14/2,0),1,0) -> 0 | AB14: =IF(AB$7=ROUNDUP($Z14/2,0),1,0) -> 0 | AC14: =IF(AC$7=ROUNDUP($Z14/2,0),1,0) -> 0 | AD14: =IF(AD$7=ROUNDUP($Z14/2,0),1,0) -> 1 | AE14: =IF(AE$7=ROUNDUP($Z14/2,0),1,0) -> 0 | AF14: =IF(AF$7=ROUNDUP($Z14/2,0),1,0) -> 0 | AG14: =IF(AG$7=ROUNDUP($Z14/2,0),1,0) -> 0 | AH14: =IF(AH$7=ROUNDUP($Z14/2,0),1,0) -> 0 | ... AJ14: =IF(AJ$7=ROUNDUP($Z14/2,0),1,0) -> 0
B15: 8 | C15: =1 -> 1 | D15: =1 -> 1 | E15: =1 -> 1 | F15: =1 -> 1 | G15: =1 -> 1 | H15: =1 -> 1 | I15: =1 -> 1 | J15: =1 -> 1 | ... L15: =1 -> 1 | N15: 8 | O15: =IF(O$7>=ROUNDUP($N15/2,0),1,0) -> 0 | P15: =IF(P$7>=ROUNDUP($N15/2,0),1,0) -> 0 | Q15: =IF(Q$7>=ROUNDUP($N15/2,0),1,0) -> 0 | R15: =IF(R$7>=ROUNDUP($N15/2,0),1,0) -> 1 | S15: =IF(S$7>=ROUNDUP($N15/2,0),1,0) -> 1 | T15: =IF(T$7>=ROUNDUP($N15/2,0),1,0) -> 1 | U15: =IF(U$7>=ROUNDUP($N15/2,0),1,0) -> 1 | V15: =IF(V$7>=ROUNDUP($N15/2,0),1,0) -> 1 | ... X15: =IF(X$7>=ROUNDUP($N15/2,0),1,0) -> 1 | Z15: 8 | AA15: =IF(AA$7=ROUNDUP($Z15/2,0),1,0) -> 0 | AB15: =IF(AB$7=ROUNDUP($Z15/2,0),1,0) -> 0 | AC15: =IF(AC$7=ROUNDUP($Z15/2,0),1,0) -> 0 | AD15: =IF(AD$7=ROUNDUP($Z15/2,0),1,0) -> 1 | AE15: =IF(AE$7=ROUNDUP($Z15/2,0),1,0) -> 0 | AF15: =IF(AF$7=ROUNDUP($Z15/2,0),1,0) -> 0 | AG15: =IF(AG$7=ROUNDUP($Z15/2,0),1,0) -> 0 | AH15: =IF(AH$7=ROUNDUP($Z15/2,0),1,0) -> 0 | ... AJ15: =IF(AJ$7=ROUNDUP($Z15/2,0),1,0) -> 0
B16: 9 | C16: =1 -> 1 | D16: =1 -> 1 | E16: =1 -> 1 | F16: =1 -> 1 | G16: =1 -> 1 | H16: =1 -> 1 | I16: =1 -> 1 | J16: =1 -> 1 | ... L16: =1 -> 1 | N16: 9 | O16: =IF(O$7>=ROUNDUP($N16/2,0),1,0) -> 0 | P16: =IF(P$7>=ROUNDUP($N16/2,0),1,0) -> 0 | Q16: =IF(Q$7>=ROUNDUP($N16/2,0),1,0) -> 0 | R16: =IF(R$7>=ROUNDUP($N16/2,0),1,0) -> 0 | S16: =IF(S$7>=ROUNDUP($N16/2,0),1,0) -> 1 | T16: =IF(T$7>=ROUNDUP($N16/2,0),1,0) -> 1 | U16: =IF(U$7>=ROUNDUP($N16/2,0),1,0) -> 1 | V16: =IF(V$7>=ROUNDUP($N16/2,0),1,0) -> 1 | ... X16: =IF(X$7>=ROUNDUP($N16/2,0),1,0) -> 1 | Z16: 9 | AA16: =IF(AA$7=ROUNDUP($Z16/2,0),1,0) -> 0 | AB16: =IF(AB$7=ROUNDUP($Z16/2,0),1,0) -> 0 | AC16: =IF(AC$7=ROUNDUP($Z16/2,0),1,0) -> 0 | AD16: =IF(AD$7=ROUNDUP($Z16/2,0),1,0) -> 0 | AE16: =IF(AE$7=ROUNDUP($Z16/2,0),1,0) -> 1 | AF16: =IF(AF$7=ROUNDUP($Z16/2,0),1,0) -> 0 | AG16: =IF(AG$7=ROUNDUP($Z16/2,0),1,0) -> 0 | AH16: =IF(AH$7=ROUNDUP($Z16/2,0),1,0) -> 0 | ... AJ16: =IF(AJ$7=ROUNDUP($Z16/2,0),1,0) -> 0
B17: 10 | C17: =1 -> 1 | D17: =1 -> 1 | E17: =1 -> 1 | F17: =1 -> 1 | G17: =1 -> 1 | H17: =1 -> 1 | I17: =1 -> 1 | J17: =1 -> 1 | ... L17: =1 -> 1 | N17: 10 | O17: =IF(O$7>=ROUNDUP($N17/2,0),1,0) -> 0 | P17: =IF(P$7>=ROUNDUP($N17/2,0),1,0) -> 0 | Q17: =IF(Q$7>=ROUNDUP($N17/2,0),1,0) -> 0 | R17: =IF(R$7>=ROUNDUP($N17/2,0),1,0) -> 0 | S17: =IF(S$7>=ROUNDUP($N17/2,0),1,0) -> 1 | T17: =IF(T$7>=ROUNDUP($N17/2,0),1,0) -> 1 | U17: =IF(U$7>=ROUNDUP($N17/2,0),1,0) -> 1 | V17: =IF(V$7>=ROUNDUP($N17/2,0),1,0) -> 1 | ... X17: =IF(X$7>=ROUNDUP($N17/2,0),1,0) -> 1 | Z17: 10 | AA17: =IF(AA$7=ROUNDUP($Z17/2,0),1,0) -> 0 | AB17: =IF(AB$7=ROUNDUP($Z17/2,0),1,0) -> 0 | AC17: =IF(AC$7=ROUNDUP($Z17/2,0),1,0) -> 0 | AD17: =IF(AD$7=ROUNDUP($Z17/2,0),1,0) -> 0 | AE17: =IF(AE$7=ROUNDUP($Z17/2,0),1,0) -> 1 | AF17: =IF(AF$7=ROUNDUP($Z17/2,0),1,0) -> 0 | AG17: =IF(AG$7=ROUNDUP($Z17/2,0),1,0) -> 0 | AH17: =IF(AH$7=ROUNDUP($Z17/2,0),1,0) -> 0 | ... AJ17: =IF(AJ$7=ROUNDUP($Z17/2,0),1,0) -> 0
B18: 11 | C18: =1 -> 1 | D18: =1 -> 1 | E18: =1 -> 1 | F18: =1 -> 1 | G18: =1 -> 1 | H18: =1 -> 1 | I18: =1 -> 1 | J18: =1 -> 1 | ... L18: =1 -> 1 | N18: 11 | O18: =IF(O$7>=ROUNDUP($N18/2,0),1,0) -> 0 | P18: =IF(P$7>=ROUNDUP($N18/2,0),1,0) -> 0 | Q18: =IF(Q$7>=ROUNDUP($N18/2,0),1,0) -> 0 | R18: =IF(R$7>=ROUNDUP($N18/2,0),1,0) -> 0 | S18: =IF(S$7>=ROUNDUP($N18/2,0),1,0) -> 0 | T18: =IF(T$7>=ROUNDUP($N18/2,0),1,0) -> 1 | U18: =IF(U$7>=ROUNDUP($N18/2,0),1,0) -> 1 | V18: =IF(V$7>=ROUNDUP($N18/2,0),1,0) -> 1 | ... X18: =IF(X$7>=ROUNDUP($N18/2,0),1,0) -> 1 | Z18: 11 | AA18: =IF(AA$7=ROUNDUP($Z18/2,0),1,0) -> 0 | AB18: =IF(AB$7=ROUNDUP($Z18/2,0),1,0) -> 0 | AC18: =IF(AC$7=ROUNDUP($Z18/2,0),1,0) -> 0 | AD18: =IF(AD$7=ROUNDUP($Z18/2,0),1,0) -> 0 | AE18: =IF(AE$7=ROUNDUP($Z18/2,0),1,0) -> 0 | AF18: =IF(AF$7=ROUNDUP($Z18/2,0),1,0) -> 1 | AG18: =IF(AG$7=ROUNDUP($Z18/2,0),1,0) -> 0 | AH18: =IF(AH$7=ROUNDUP($Z18/2,0),1,0) -> 0 | ... AJ18: =IF(AJ$7=ROUNDUP($Z18/2,0),1,0) -> 0
B19: 12 | C19: =1 -> 1 | D19: =1 -> 1 | E19: =1 -> 1 | F19: =1 -> 1 | G19: =1 -> 1 | H19: =1 -> 1 | I19: =1 -> 1 | J19: =1 -> 1 | ... L19: =1 -> 1 | N19: 12 | O19: =IF(O$7>=ROUNDUP($N19/2,0),1,0) -> 0 | P19: =IF(P$7>=ROUNDUP($N19/2,0),1,0) -> 0 | Q19: =IF(Q$7>=ROUNDUP($N19/2,0),1,0) -> 0 | R19: =IF(R$7>=ROUNDUP($N19/2,0),1,0) -> 0 | S19: =IF(S$7>=ROUNDUP($N19/2,0),1,0) -> 0 | T19: =IF(T$7>=ROUNDUP($N19/2,0),1,0) -> 1 | U19: =IF(U$7>=ROUNDUP($N19/2,0),1,0) -> 1 | V19: =IF(V$7>=ROUNDUP($N19/2,0),1,0) -> 1 | ... X19: =IF(X$7>=ROUNDUP($N19/2,0),1,0) -> 1 | Z19: 12 | AA19: =IF(AA$7=ROUNDUP($Z19/2,0),1,0) -> 0 | AB19: =IF(AB$7=ROUNDUP($Z19/2,0),1,0) -> 0 | AC19: =IF(AC$7=ROUNDUP($Z19/2,0),1,0) -> 0 | AD19: =IF(AD$7=ROUNDUP($Z19/2,0),1,0) -> 0 | AE19: =IF(AE$7=ROUNDUP($Z19/2,0),1,0) -> 0 | AF19: =IF(AF$7=ROUNDUP($Z19/2,0),1,0) -> 1 | AG19: =IF(AG$7=ROUNDUP($Z19/2,0),1,0) -> 0 | AH19: =IF(AH$7=ROUNDUP($Z19/2,0),1,0) -> 0 | ... AJ19: =IF(AJ$7=ROUNDUP($Z19/2,0),1,0) -> 0
... B27: 20 | C27: =1 -> 1 | D27: =1 -> 1 | E27: =1 -> 1 | F27: =1 -> 1 | G27: =1 -> 1 | H27: =1 -> 1 | I27: =1 -> 1 | J27: =1 -> 1 | ... L27: =1 -> 1 | N27: 20 | O27: =IF(O$7>=ROUNDUP($N27/2,0),1,0) -> 0 | P27: =IF(P$7>=ROUNDUP($N27/2,0),1,0) -> 0 | Q27: =IF(Q$7>=ROUNDUP($N27/2,0),1,0) -> 0 | R27: =IF(R$7>=ROUNDUP($N27/2,0),1,0) -> 0 | S27: =IF(S$7>=ROUNDUP($N27/2,0),1,0) -> 0 | T27: =IF(T$7>=ROUNDUP($N27/2,0),1,0) -> 0 | U27: =IF(U$7>=ROUNDUP($N27/2,0),1,0) -> 0 | V27: =IF(V$7>=ROUNDUP($N27/2,0),1,0) -> 0 | ... X27: =IF(X$7>=ROUNDUP($N27/2,0),1,0) -> 1 | Z27: 20 | AA27: =IF(AA$7=ROUNDUP($Z27/2,0),1,0) -> 0 | AB27: =IF(AB$7=ROUNDUP($Z27/2,0),1,0) -> 0 | AC27: =IF(AC$7=ROUNDUP($Z27/2,0),1,0) -> 0 | AD27: =IF(AD$7=ROUNDUP($Z27/2,0),1,0) -> 0 | AE27: =IF(AE$7=ROUNDUP($Z27/2,0),1,0) -> 0 | AF27: =IF(AF$7=ROUNDUP($Z27/2,0),1,0) -> 0 | AG27: =IF(AG$7=ROUNDUP($Z27/2,0),1,0) -> 0 | AH27: =IF(AH$7=ROUNDUP($Z27/2,0),1,0) -> 0 | ... AJ27: =IF(AJ$7=ROUNDUP($Z27/2,0),1,0) -> 1
A30: Entscheidungsstrukturen (Entscheidungsträger x Gelegenheiten)
B31: D0 unsegmentiert | N31: D1 hierarchisch | Z31: D2 spezialisiert
B32: i \ j | C32: 1 | D32: 2 | E32: 3 | F32: 4 | G32: 5 | H32: 6 | I32: 7 | J32: 8 | K32: 9 | L32: 10 | N32: i \ j | O32: 1 | P32: 2 | Q32: 3 | R32: 4 | S32: 5 | T32: 6 | U32: 7 | V32: 8 | W32: 9 | X32: 10 | Z32: i \ j | AA32: 1 | AB32: 2 | AC32: 3 | AD32: 4 | AE32: 5 | AF32: 6 | AG32: 7 | AH32: 8 | AI32: 9 | AJ32: 10
B33: 1 | C33: =1 -> 1 | D33: =1 -> 1 | E33: =1 -> 1 | F33: =1 -> 1 | G33: =1 -> 1 | H33: =1 -> 1 | I33: =1 -> 1 | J33: =1 -> 1 | ... L33: =1 -> 1 | N33: 1 | O33: =IF(O$32>=$N33,1,0) -> 1 | P33: =IF(P$32>=$N33,1,0) -> 1 | Q33: =IF(Q$32>=$N33,1,0) -> 1 | R33: =IF(R$32>=$N33,1,0) -> 1 | S33: =IF(S$32>=$N33,1,0) -> 1 | T33: =IF(T$32>=$N33,1,0) -> 1 | U33: =IF(U$32>=$N33,1,0) -> 1 | V33: =IF(V$32>=$N33,1,0) -> 1 | ... X33: =IF(X$32>=$N33,1,0) -> 1 | Z33: 1 | AA33: =IF(AA$32=$Z33,1,0) -> 1 | AB33: =IF(AB$32=$Z33,1,0) -> 0 | AC33: =IF(AC$32=$Z33,1,0) -> 0 | AD33: =IF(AD$32=$Z33,1,0) -> 0 | AE33: =IF(AE$32=$Z33,1,0) -> 0 | AF33: =IF(AF$32=$Z33,1,0) -> 0 | AG33: =IF(AG$32=$Z33,1,0) -> 0 | AH33: =IF(AH$32=$Z33,1,0) -> 0 | ... AJ33: =IF(AJ$32=$Z33,1,0) -> 0
B34: 2 | C34: =1 -> 1 | D34: =1 -> 1 | E34: =1 -> 1 | F34: =1 -> 1 | G34: =1 -> 1 | H34: =1 -> 1 | I34: =1 -> 1 | J34: =1 -> 1 | ... L34: =1 -> 1 | N34: 2 | O34: =IF(O$32>=$N34,1,0) -> 0 | P34: =IF(P$32>=$N34,1,0) -> 1 | Q34: =IF(Q$32>=$N34,1,0) -> 1 | R34: =IF(R$32>=$N34,1,0) -> 1 | S34: =IF(S$32>=$N34,1,0) -> 1 | T34: =IF(T$32>=$N34,1,0) -> 1 | U34: =IF(U$32>=$N34,1,0) -> 1 | V34: =IF(V$32>=$N34,1,0) -> 1 | ... X34: =IF(X$32>=$N34,1,0) -> 1 | Z34: 2 | AA34: =IF(AA$32=$Z34,1,0) -> 0 | AB34: =IF(AB$32=$Z34,1,0) -> 1 | AC34: =IF(AC$32=$Z34,1,0) -> 0 | AD34: =IF(AD$32=$Z34,1,0) -> 0 | AE34: =IF(AE$32=$Z34,1,0) -> 0 | AF34: =IF(AF$32=$Z34,1,0) -> 0 | AG34: =IF(AG$32=$Z34,1,0) -> 0 | AH34: =IF(AH$32=$Z34,1,0) -> 0 | ... AJ34: =IF(AJ$32=$Z34,1,0) -> 0
B35: 3 | C35: =1 -> 1 | D35: =1 -> 1 | E35: =1 -> 1 | F35: =1 -> 1 | G35: =1 -> 1 | H35: =1 -> 1 | I35: =1 -> 1 | J35: =1 -> 1 | ... L35: =1 -> 1 | N35: 3 | O35: =IF(O$32>=$N35,1,0) -> 0 | P35: =IF(P$32>=$N35,1,0) -> 0 | Q35: =IF(Q$32>=$N35,1,0) -> 1 | R35: =IF(R$32>=$N35,1,0) -> 1 | S35: =IF(S$32>=$N35,1,0) -> 1 | T35: =IF(T$32>=$N35,1,0) -> 1 | U35: =IF(U$32>=$N35,1,0) -> 1 | V35: =IF(V$32>=$N35,1,0) -> 1 | ... X35: =IF(X$32>=$N35,1,0) -> 1 | Z35: 3 | AA35: =IF(AA$32=$Z35,1,0) -> 0 | AB35: =IF(AB$32=$Z35,1,0) -> 0 | AC35: =IF(AC$32=$Z35,1,0) -> 1 | AD35: =IF(AD$32=$Z35,1,0) -> 0 | AE35: =IF(AE$32=$Z35,1,0) -> 0 | AF35: =IF(AF$32=$Z35,1,0) -> 0 | AG35: =IF(AG$32=$Z35,1,0) -> 0 | AH35: =IF(AH$32=$Z35,1,0) -> 0 | ... AJ35: =IF(AJ$32=$Z35,1,0) -> 0
B36: 4 | C36: =1 -> 1 | D36: =1 -> 1 | E36: =1 -> 1 | F36: =1 -> 1 | G36: =1 -> 1 | H36: =1 -> 1 | I36: =1 -> 1 | J36: =1 -> 1 | ... L36: =1 -> 1 | N36: 4 | O36: =IF(O$32>=$N36,1,0) -> 0 | P36: =IF(P$32>=$N36,1,0) -> 0 | Q36: =IF(Q$32>=$N36,1,0) -> 0 | R36: =IF(R$32>=$N36,1,0) -> 1 | S36: =IF(S$32>=$N36,1,0) -> 1 | T36: =IF(T$32>=$N36,1,0) -> 1 | U36: =IF(U$32>=$N36,1,0) -> 1 | V36: =IF(V$32>=$N36,1,0) -> 1 | ... X36: =IF(X$32>=$N36,1,0) -> 1 | Z36: 4 | AA36: =IF(AA$32=$Z36,1,0) -> 0 | AB36: =IF(AB$32=$Z36,1,0) -> 0 | AC36: =IF(AC$32=$Z36,1,0) -> 0 | AD36: =IF(AD$32=$Z36,1,0) -> 1 | AE36: =IF(AE$32=$Z36,1,0) -> 0 | AF36: =IF(AF$32=$Z36,1,0) -> 0 | AG36: =IF(AG$32=$Z36,1,0) -> 0 | AH36: =IF(AH$32=$Z36,1,0) -> 0 | ... AJ36: =IF(AJ$32=$Z36,1,0) -> 0
B37: 5 | C37: =1 -> 1 | D37: =1 -> 1 | E37: =1 -> 1 | F37: =1 -> 1 | G37: =1 -> 1 | H37: =1 -> 1 | I37: =1 -> 1 | J37: =1 -> 1 | ... L37: =1 -> 1 | N37: 5 | O37: =IF(O$32>=$N37,1,0) -> 0 | P37: =IF(P$32>=$N37,1,0) -> 0 | Q37: =IF(Q$32>=$N37,1,0) -> 0 | R37: =IF(R$32>=$N37,1,0) -> 0 | S37: =IF(S$32>=$N37,1,0) -> 1 | T37: =IF(T$32>=$N37,1,0) -> 1 | U37: =IF(U$32>=$N37,1,0) -> 1 | V37: =IF(V$32>=$N37,1,0) -> 1 | ... X37: =IF(X$32>=$N37,1,0) -> 1 | Z37: 5 | AA37: =IF(AA$32=$Z37,1,0) -> 0 | AB37: =IF(AB$32=$Z37,1,0) -> 0 | AC37: =IF(AC$32=$Z37,1,0) -> 0 | AD37: =IF(AD$32=$Z37,1,0) -> 0 | AE37: =IF(AE$32=$Z37,1,0) -> 1 | AF37: =IF(AF$32=$Z37,1,0) -> 0 | AG37: =IF(AG$32=$Z37,1,0) -> 0 | AH37: =IF(AH$32=$Z37,1,0) -> 0 | ... AJ37: =IF(AJ$32=$Z37,1,0) -> 0
B38: 6 | C38: =1 -> 1 | D38: =1 -> 1 | E38: =1 -> 1 | F38: =1 -> 1 | G38: =1 -> 1 | H38: =1 -> 1 | I38: =1 -> 1 | J38: =1 -> 1 | ... L38: =1 -> 1 | N38: 6 | O38: =IF(O$32>=$N38,1,0) -> 0 | P38: =IF(P$32>=$N38,1,0) -> 0 | Q38: =IF(Q$32>=$N38,1,0) -> 0 | R38: =IF(R$32>=$N38,1,0) -> 0 | S38: =IF(S$32>=$N38,1,0) -> 0 | T38: =IF(T$32>=$N38,1,0) -> 1 | U38: =IF(U$32>=$N38,1,0) -> 1 | V38: =IF(V$32>=$N38,1,0) -> 1 | ... X38: =IF(X$32>=$N38,1,0) -> 1 | Z38: 6 | AA38: =IF(AA$32=$Z38,1,0) -> 0 | AB38: =IF(AB$32=$Z38,1,0) -> 0 | AC38: =IF(AC$32=$Z38,1,0) -> 0 | AD38: =IF(AD$32=$Z38,1,0) -> 0 | AE38: =IF(AE$32=$Z38,1,0) -> 0 | AF38: =IF(AF$32=$Z38,1,0) -> 1 | AG38: =IF(AG$32=$Z38,1,0) -> 0 | AH38: =IF(AH$32=$Z38,1,0) -> 0 | ... AJ38: =IF(AJ$32=$Z38,1,0) -> 0
B39: 7 | C39: =1 -> 1 | D39: =1 -> 1 | E39: =1 -> 1 | F39: =1 -> 1 | G39: =1 -> 1 | H39: =1 -> 1 | I39: =1 -> 1 | J39: =1 -> 1 | ... L39: =1 -> 1 | N39: 7 | O39: =IF(O$32>=$N39,1,0) -> 0 | P39: =IF(P$32>=$N39,1,0) -> 0 | Q39: =IF(Q$32>=$N39,1,0) -> 0 | R39: =IF(R$32>=$N39,1,0) -> 0 | S39: =IF(S$32>=$N39,1,0) -> 0 | T39: =IF(T$32>=$N39,1,0) -> 0 | U39: =IF(U$32>=$N39,1,0) -> 1 | V39: =IF(V$32>=$N39,1,0) -> 1 | ... X39: =IF(X$32>=$N39,1,0) -> 1 | Z39: 7 | AA39: =IF(AA$32=$Z39,1,0) -> 0 | AB39: =IF(AB$32=$Z39,1,0) -> 0 | AC39: =IF(AC$32=$Z39,1,0) -> 0 | AD39: =IF(AD$32=$Z39,1,0) -> 0 | AE39: =IF(AE$32=$Z39,1,0) -> 0 | AF39: =IF(AF$32=$Z39,1,0) -> 0 | AG39: =IF(AG$32=$Z39,1,0) -> 1 | AH39: =IF(AH$32=$Z39,1,0) -> 0 | ... AJ39: =IF(AJ$32=$Z39,1,0) -> 0
B40: 8 | C40: =1 -> 1 | D40: =1 -> 1 | E40: =1 -> 1 | F40: =1 -> 1 | G40: =1 -> 1 | H40: =1 -> 1 | I40: =1 -> 1 | J40: =1 -> 1 | ... L40: =1 -> 1 | N40: 8 | O40: =IF(O$32>=$N40,1,0) -> 0 | P40: =IF(P$32>=$N40,1,0) -> 0 | Q40: =IF(Q$32>=$N40,1,0) -> 0 | R40: =IF(R$32>=$N40,1,0) -> 0 | S40: =IF(S$32>=$N40,1,0) -> 0 | T40: =IF(T$32>=$N40,1,0) -> 0 | U40: =IF(U$32>=$N40,1,0) -> 0 | V40: =IF(V$32>=$N40,1,0) -> 1 | ... X40: =IF(X$32>=$N40,1,0) -> 1 | Z40: 8 | AA40: =IF(AA$32=$Z40,1,0) -> 0 | AB40: =IF(AB$32=$Z40,1,0) -> 0 | AC40: =IF(AC$32=$Z40,1,0) -> 0 | AD40: =IF(AD$32=$Z40,1,0) -> 0 | AE40: =IF(AE$32=$Z40,1,0) -> 0 | AF40: =IF(AF$32=$Z40,1,0) -> 0 | AG40: =IF(AG$32=$Z40,1,0) -> 0 | AH40: =IF(AH$32=$Z40,1,0) -> 1 | ... AJ40: =IF(AJ$32=$Z40,1,0) -> 0
B41: 9 | C41: =1 -> 1 | D41: =1 -> 1 | E41: =1 -> 1 | F41: =1 -> 1 | G41: =1 -> 1 | H41: =1 -> 1 | I41: =1 -> 1 | J41: =1 -> 1 | ... L41: =1 -> 1 | N41: 9 | O41: =IF(O$32>=$N41,1,0) -> 0 | P41: =IF(P$32>=$N41,1,0) -> 0 | Q41: =IF(Q$32>=$N41,1,0) -> 0 | R41: =IF(R$32>=$N41,1,0) -> 0 | S41: =IF(S$32>=$N41,1,0) -> 0 | T41: =IF(T$32>=$N41,1,0) -> 0 | U41: =IF(U$32>=$N41,1,0) -> 0 | V41: =IF(V$32>=$N41,1,0) -> 0 | ... X41: =IF(X$32>=$N41,1,0) -> 1 | Z41: 9 | AA41: =IF(AA$32=$Z41,1,0) -> 0 | AB41: =IF(AB$32=$Z41,1,0) -> 0 | AC41: =IF(AC$32=$Z41,1,0) -> 0 | AD41: =IF(AD$32=$Z41,1,0) -> 0 | AE41: =IF(AE$32=$Z41,1,0) -> 0 | AF41: =IF(AF$32=$Z41,1,0) -> 0 | AG41: =IF(AG$32=$Z41,1,0) -> 0 | AH41: =IF(AH$32=$Z41,1,0) -> 0 | ... AJ41: =IF(AJ$32=$Z41,1,0) -> 0
B42: 10 | C42: =1 -> 1 | D42: =1 -> 1 | E42: =1 -> 1 | F42: =1 -> 1 | G42: =1 -> 1 | H42: =1 -> 1 | I42: =1 -> 1 | J42: =1 -> 1 | ... L42: =1 -> 1 | N42: 10 | O42: =IF(O$32>=$N42,1,0) -> 0 | P42: =IF(P$32>=$N42,1,0) -> 0 | Q42: =IF(Q$32>=$N42,1,0) -> 0 | R42: =IF(R$32>=$N42,1,0) -> 0 | S42: =IF(S$32>=$N42,1,0) -> 0 | T42: =IF(T$32>=$N42,1,0) -> 0 | U42: =IF(U$32>=$N42,1,0) -> 0 | V42: =IF(V$32>=$N42,1,0) -> 0 | ... X42: =IF(X$32>=$N42,1,0) -> 1 | Z42: 10 | AA42: =IF(AA$32=$Z42,1,0) -> 0 | AB42: =IF(AB$32=$Z42,1,0) -> 0 | AC42: =IF(AC$32=$Z42,1,0) -> 0 | AD42: =IF(AD$32=$Z42,1,0) -> 0 | AE42: =IF(AE$32=$Z42,1,0) -> 0 | AF42: =IF(AF$32=$Z42,1,0) -> 0 | AG42: =IF(AG$32=$Z42,1,0) -> 0 | AH42: =IF(AH$32=$Z42,1,0) -> 0 | ... AJ42: =IF(AJ$32=$Z42,1,0) -> 1
A45: Energieverteilungen je Entscheidungsträger (S. 7)
A46: Entscheidungsträger | B46: 1 | C46: 2 | D46: 3 | E46: 4 | F46: 5 | G46: 6 | H46: 7 | I46: 8 | J46: 9 | K46: 10 | L46: Summe
A47: E0 Wichtige weniger | B47: =B$46/10 -> 0.1 | C47: =C$46/10 -> 0.2 | D47: =D$46/10 -> 0.3 | E47: =E$46/10 -> 0.4 | F47: =F$46/10 -> 0.5 | G47: =G$46/10 -> 0.6 | H47: =H$46/10 -> 0.7 | I47: =I$46/10 -> 0.8 | ... K47: =K$46/10 -> 1 | L47: =SUM(B47:K47) -> 5.5
A48: E1 gleich | B48: =0.55 -> 0.55 | C48: =0.55 -> 0.55 | D48: =0.55 -> 0.55 | E48: =0.55 -> 0.55 | F48: =0.55 -> 0.55 | G48: =0.55 -> 0.55 | H48: =0.55 -> 0.55 | I48: =0.55 -> 0.55 | ... K48: =0.55 -> 0.55 | L48: =SUM(B48:K48) -> 5.5
A49: E2 Wichtige mehr | B49: =(11-B$46)/10 -> 1 | C49: =(11-C$46)/10 -> 0.9 | D49: =(11-D$46)/10 -> 0.8 | E49: =(11-E$46)/10 -> 0.7 | F49: =(11-F$46)/10 -> 0.6 | G49: =(11-G$46)/10 -> 0.5 | H49: =(11-H$46)/10 -> 0.4 | I49: =(11-I$46)/10 -> 0.3 | ... K49: =(11-K$46)/10 -> 0.1 | L49: =SUM(B49:K49) -> 5.5
A52: Eintrittsfolgen (S. 5) und daraus berechnete Eintrittsperioden
A53: Die Folgen nennen, welche Gelegenheit bzw. welches Problem in Periode 1, 2, ... eintritt. Eintrittsperiode je Gelegenheit = Position in der Folge; je Problem = Position aufgerundet halbiert (zwei Probleme je Periode).
A54: Position in der Folge | B54: 1 | C54: 2 | D54: 3 | E54: 4 | F54: 5 | G54: 6 | H54: 7 | I54: 8 | J54: 9 | K54: 10 | L54: 11 | M54: 12 | N54: 13 | O54: 14 | P54: 15 | Q54: 16 | R54: 17 | S54: 18 | T54: 19 | U54: 20
...

Sheet CMO_Kennzahlen
A1: Cohen, March und Olsen (1972): Kennzahlen des Fortran-Programms und ihre Verwendung
A2: Zählweisen am Scan des Listings (S. 20 bis 24) in hoher Auflösung gelesen. Der OCR-Text des PDF enthält an dieser Stelle Fehler.
A4: Fortran-Variable | B4: Bezeichnung im Anhang (S. 17, 18) | C4: Begriff im Artikel (S. 8, 9) | D4: Zählweise laut Listing | E4: Ausgabespalte | F4: Verwendet in | G4: Anmerkung
A5: KZ | B5: Choice failures | C5: Entscheidungsschwierigkeit, Maß 1 (Zahl nicht getroffener Entscheidungen) | D5: Zahl der Gelegenheiten, die in Periode 20 noch aktiv und nicht entschieden sind (Schleife DO 310 über Perioden 1 bis 20). | E5: 1 | F5: Textwert S. 9 (Mittel 1,0); Wahlausfälle nach Wichtigkeit S. 11
A6: KY | B6: Choice persistence | C6: Entscheidungsschwierigkeit, verwendetes Maß 2 (im Abschnitt zu Eigenschaft 4 auch Entscheidungszeit) | D6: Summe der Perioden 1 bis 20, in denen eine Gelegenheit aktiv und nicht entschieden ist, über alle Gelegenheiten (DO 310 I=1,NTP). | E6: 2 | F6: Tab. 2 Spalte 3; Tab. 5 Entscheidungszeit (vermutlich) | G6: Laut Artikel hoch korreliert mit KZ; gewählt wegen höherer Varianz.
A7: KX | B7: Decision maker velocity | C7: Aktivität der Entscheidungsträger, verwendetes Maß b | D7: Zahl der Wechsel der zugeordneten Gelegenheit zwischen aufeinanderfolgenden Perioden, Vergleich ab Periode 2 (DO 330 I=2,NTP). Wechsel zu oder von keiner Gelegenheit zählen mit. | E7: 3 | F7: Tab. 2 Spalte 2; Tab. 5 Aktivität der Entscheidungsträger (vermutlich) | G7: Laut Artikel hoch korreliert mit den Maßen a, c, d.
A8: KW | B8: Problem failures | C8: Problemaktivität, Maß 1 (ungelöste Probleme am Ende) | D8: 20 minus Zahl der Probleme mit Status gelöst in Periode 20 (DO 350 I=1,NTP, Auswertung bei I = NTP). | E8: 4 | F8: Textwert S. 9 (Mittel 12,3)
A9: KV | B9: Problem velocity | C9: Problemaktivität, Maß 2 (Wechsel zwischen Gelegenheiten) | D9: Zahl der Änderungen des Problemstatus zwischen aufeinanderfolgenden Perioden ab Periode 2 (DO 370 I=2,NTP). Gezählt werden auch Eintritt, Anhängen, Ablösen und Lösen, nicht nur Wechsel zwischen Gelegenheiten. | E9: 5 | F9: nicht berichtet | G9: Status je Periode: -1 nicht eingetreten, 0 aktiv ohne Gelegenheit, Nummer der Gelegenheit, 1000 gelöst.
A10: KU | B10: Problem latency | C10: Problemlatenz | D10: Summe der Perioden 1 bis 20, in denen ein Problem aktiv, aber keiner Gelegenheit zugeordnet ist (Status 0; DO 350 I=1,NTP). | E10: 6 | F10: Tab. 5 Problemlatenz
A11: KT | B11: Problem persistence | C11: Problemaktivität, verwendetes Maß 3 | D11: Summe der Perioden 1 bis 20, in denen ein Problem einer Gelegenheit zugeordnet ist (Status weder -1 noch 0 noch 1000; DO 350 I=1,NTP). | E11: 7 | F11: Tab. 2 Spalte 1; Tab. 5 Problemaktivität | G11: Der OCR-Text des PDF zeigt fälschlich I=2 als Schleifenbeginn; der Scan zeigt I=1.
A12: KS | B12: Decision maker inactivity | C12: Komplement zu Maß a der Aktivität der Entscheidungsträger | D12: Zahl der Entscheidungsträger-Perioden ohne Zuordnung, in jeder Periode 1 bis 20 nach der Zuordnung gezählt. | E12: 8 | F12: nicht berichtet | G12: Maß a (Perioden mit Zuordnung) = 10 x 20 minus KS.
A13: XR | B13: Energy reserve | C13: Komplement zu Maß c (verfügbare und genutzte effektive Energie) | D13: Summe der effektiven Energie (Energie mal Lösungskoeffizient) nicht zugeordneter Entscheidungsträger über alle Perioden. | E13: 9 | F13: nicht berichtet | G13: Bei konstantem Koeffizienten 0,6 gilt Maß c = 66 minus XR.
A14: XS | B14: Energy wastage | C14: Maß d (Energie über dem Bedarf) | D14: Summe über getroffene Entscheidungen von eingesetzter minus benötigter effektiver Energie im Entscheidungszeitpunkt. | E14: 10 | F14: nicht berichtet
A15: (keine) | B15: nicht im Programm | C15: Entscheidungsstil: Resolution, Oversight, Flight (S. 8) | D15: Nicht ausgegeben. Muss aus den Verläufen (IO = 2) bestimmt werden: Resolution, wenn beim Entscheiden Probleme angehängt sind; Flight, wenn zuvor Probleme angehängt waren und abgewandert sind; sonst Oversight. | F15: Tab. 1; Tab. 2 Spalte 4; Tab. 4; Tab. 5 | G15: Die Abgrenzung von Flight und Oversight über die Verlaufsdaten ist eine Interpretation der Definition auf S. 8 (vgl. Bendor, Moe und Shotts 2001).
A17: Ausgabezeile je Variante (FORMAT 1019, S. 24): LOAD, PR.ACC., DEC.STR., EN.DIST., danach KZ, KY, KX, KW, KV, KU, KT, KS, XR, XS.
A18: Schleifenreihenfolge (S. 20): Last außen, dann Zugangsstruktur, Entscheidungsstruktur, Energieverteilung innen.
A19: Organisationstyp-Code in Tab. 5: Ziffern in der Reihenfolge Last, Zugang, Entscheidungsstruktur, Energieverteilung (aus der Spezifikation S. 14 abgeleitet).
A20: Für Tab. 5 nennt der Artikel die verwendeten Maße nicht erneut; die Zuordnung zu KT, KU, KX und KY ist naheliegend, aber nicht ausdrücklich belegt.

Sheet CMO_Tab1
A1: Tabelle 1: Anteil der getroffenen Entscheidungen, die Probleme lösen, nach Last und Zugangsstruktur
A2: Quelle: Cohen, March und Olsen (1972), S. 9. Mittel über die vier Kombinationen der Eintrittsfolgen. Werte am Scan geprüft.
A4: Last | B4: Alle Zugangsstrukturen | C4: Unsegmentiert | D4: Hierarchisch | E4: Spezialisiert | F4: Mittel der drei Strukturen (Formel) | G4: Differenz zu Alle (Formel)
A5: Leicht (Last 0) | B5: 0.55 | C5: 0.38 | D5: 0.61 | E5: 0.65 | F5: =AVERAGE(C5:E5) -> 0.54666667 | G5: =F5-B5 -> -0.0033333333
A6: Mittel (Last 1) | B6: 0.3 | C6: 0.04 | D6: 0.27 | E6: 0.6 | F6: =AVERAGE(C6:E6) -> 0.30333333 | G6: =F6-B6 -> 0.0033333333
A7: Schwer (Last 2) | B7: 0.36 | C7: 0.35 | D7: 0.23 | E7: 0.5 | F7: =AVERAGE(C7:E7) -> 0.36 | G7: =F7-B7 -> 0
A8: Alle Lasten | B8: 0.4 | C8: 0.26 | D8: 0.37 | E8: 0.58 | F8: =AVERAGE(C8:E8) -> 0.40333333 | G8: =F8-B8 -> 0.0033333333
A9: Mittel der drei Lasten (Formel) | B9: =AVERAGE(B5:B7) -> 0.40333333 | C9: =AVERAGE(C5:C7) -> 0.25666667 | D9: =AVERAGE(D5:D7) -> 0.37 | E9: =AVERAGE(E5:E7) -> 0.58333333
A10: Differenz zu Zeile Alle (Formel) | B10: =B9-B8 -> 0.0033333333 | C10: =C9-C8 -> -0.0033333333 | D10: =D9-D8 -> 0 | E10: =E9-E8 -> 0.0033333333
B11: leicht | C11: mittel | D11: schwer
A12: Komplement 1 minus Alle (Formel), entspricht Tab. 2 Spalte 4 | B12: =1-B5 -> 0.45 | C12: =1-B6 -> 0.7 | D12: =1-B7 -> 0.64
A14: Die Rand- und Gesamtwerte stimmen bis auf Rundung mit dem ungewichteten Mittel der Zellen überein. Ob intern über Läufe oder über gepoolte Entscheidungen gemittelt wurde, nennt der Artikel nicht.
A15: Läufe je Zelle aus dem Versuchsplan: 3 Entscheidungsstrukturen x 3 Energieverteilungen x 4 Eintrittsfolgen = 36; Randzeilen und Randspalten 108; gesamt 324.
A16: Spalte unsegmentiert zeigt einen nicht monotonen Lastverlauf. Laut Eigenschaft 1 (S. 9) ist Resolution nur bei spezialisiertem Zugang oder einigen Bedingungen leichter Last der häufigste Stil.

Sheet CMO_Tab2
A1: Tabelle 2: Wirkung der Last unter den vier Kombinationen der Eintrittsfolgen
A2: Quelle: Cohen, March und Olsen (1972), S. 10. Mittel über alle 27 Strukturkombinationen und vier Eintrittsfolgen je Last. Werte am Scan geprüft.
A4: Last | B4: Mittlere Problemaktivität (KT) | C4: Mittlere Aktivität der Entscheidungsträger (KX) | D4: Mittlere Entscheidungsschwierigkeit (KY) | E4: Anteil Entscheidungen durch Flight oder Oversight | F4: 1 minus Tab. 1 Alle (Formel) | G4: Differenz (Formel)
A5: Leicht (Last 0) | B5: 114.9 | C5: 60.9 | D5: 19.5 | E5: 0.45 | F5: =1-CMO_Tab1!B5 -> 0.45 | G5: =E5-F5 -> 0
A6: Mittel (Last 1) | B6: 204.3 | C6: 63.8 | D6: 32.9 | E6: 0.7 | F6: =1-CMO_Tab1!B6 -> 0.7 | G6: =E6-F6 -> 0
A7: Schwer (Last 2) | B7: 211.1 | C7: 76.6 | D7: 46.1 | E7: 0.64 | F7: =1-CMO_Tab1!B7 -> 0.64 | G7: =E7-F7 -> 0
A9: Spalte 4 ist das Komplement der Spalte Alle aus Tabelle 1; die Differenz ist 0.
A10: Problemaktivität, Aktivität der Entscheidungsträger und Entscheidungsschwierigkeit steigen monoton mit der Last; der Anteil Flight oder Oversight nicht.
A11: Messgrößen laut S. 8 und 9: Problemaktivität = KT, Aktivität der Entscheidungsträger = KX, Entscheidungsschwierigkeit = KY (siehe Blatt CMO_Kennzahlen).

Sheet CMO_Tab3_Tab4
A1: Tabellen 3 und 4 sowie Wahlausfälle nach Wichtigkeit
A2: Quelle: Cohen, March und Olsen (1972), S. 10 und 11. Werte am Scan geprüft. Zellbesetzungen per Formel aus den Eintrittsfolgen berechnet.
A4: Tabelle 3: Anteil gelöster Probleme nach Wichtigkeit und Ankunft (nur hierarchischer Zugang)
A5: Wichtigkeit des Problems | B5: Früh (erste 10 Probleme) | C5: Spät (letzte 10 Probleme) | E5: Zellbesetzung (Probleme je Zelle) | F5: Folge (a) | G5: Folge (b)
A6: Hoch (Probleme 1 bis 10) | B6: 0.46 | C6: 0.44 | E6: hoch, früh | F6: =SUMPRODUCT((CMO_Strukturen!$B$60:$U$60<=10)*(CMO_Strukturen!$B$63:$U$63<=5)) -> 4 | G6: =SUMPRODUCT((CMO_Strukturen!$B$60:$U$60<=10)*(CMO_Strukturen!$B$64:$U$64<=5)) -> 6
A7: Niedrig (Probleme 11 bis 20) | B7: 0.48 | C7: 0.25 | E7: hoch, spät | F7: =SUMPRODUCT((CMO_Strukturen!$B$60:$U$60<=10)*(CMO_Strukturen!$B$63:$U$63>5)) -> 6 | G7: =SUMPRODUCT((CMO_Strukturen!$B$60:$U$60<=10)*(CMO_Strukturen!$B$64:$U$64>5)) -> 4
E8: niedrig, früh | F8: =SUMPRODUCT((CMO_Strukturen!$B$60:$U$60>10)*(CMO_Strukturen!$B$63:$U$63<=5)) -> 6 | G8: =SUMPRODUCT((CMO_Strukturen!$B$60:$U$60>10)*(CMO_Strukturen!$B$64:$U$64<=5)) -> 4
E9: niedrig, spät | F9: =SUMPRODUCT((CMO_Strukturen!$B$60:$U$60>10)*(CMO_Strukturen!$B$63:$U$63>5)) -> 4 | G9: =SUMPRODUCT((CMO_Strukturen!$B$60:$U$60>10)*(CMO_Strukturen!$B$64:$U$64>5)) -> 6
A10: Früh = Probleme mit Eintritt in den Perioden 1 bis 5. Über beide Problemfolgen gepoolt ist jede Zelle gleich besetzt (je 10 Probleme pro Paar von Läufen).
A11: Laut Text entsteht so eine Warteschlange nach Wichtigkeit zulasten später, wenig wichtiger Probleme, besonders bei schwerer Last; sie ist nicht als Annahme vorgegeben.
A13: Tabelle 4: Anteil der Entscheidungen durch Flight oder Oversight nach Wichtigkeit und Ankunft
A14: (nur Läufe mit hierarchischem Zugang oder hierarchischer Entscheidungsstruktur)
A15: Wichtigkeit der Entscheidung | B15: Früh (erste 5 Gelegenheiten) | C15: Spät (letzte 5 Gelegenheiten) | E15: Zellbesetzung (Gelegenheiten je Zelle) | F15: Folge (a) | G15: Folge (b)
A16: Hoch (Gelegenheiten 1 bis 5) | B16: 0.86 | C16: 0.65 | E16: hoch, früh | F16: =SUMPRODUCT((CMO_Strukturen!$B$60:$K$60<=5)*(CMO_Strukturen!$B$61:$K$61<=5)) -> 2 | G16: =SUMPRODUCT((CMO_Strukturen!$B$60:$K$60<=5)*(CMO_Strukturen!$B$62:$K$62<=5)) -> 2
A17: Niedrig (Gelegenheiten 6 bis 10) | B17: 0.54 | C17: 0.6 | E17: hoch, spät | F17: =SUMPRODUCT((CMO_Strukturen!$B$60:$K$60<=5)*(CMO_Strukturen!$B$61:$K$61>5)) -> 3 | G17: =SUMPRODUCT((CMO_Strukturen!$B$60:$K$60<=5)*(CMO_Strukturen!$B$62:$K$62>5)) -> 3
E18: niedrig, früh | F18: =SUMPRODUCT((CMO_Strukturen!$B$60:$K$60>5)*(CMO_Strukturen!$B$61:$K$61<=5)) -> 3 | G18: =SUMPRODUCT((CMO_Strukturen!$B$60:$K$60>5)*(CMO_Strukturen!$B$62:$K$62<=5)) -> 3
E19: niedrig, spät | F19: =SUMPRODUCT((CMO_Strukturen!$B$60:$K$60>5)*(CMO_Strukturen!$B$61:$K$61>5)) -> 2 | G19: =SUMPRODUCT((CMO_Strukturen!$B$60:$K$60>5)*(CMO_Strukturen!$B$62:$K$62>5)) -> 2
A20: Beide Folgen der Gelegenheiten haben dieselbe Besetzung (2, 3, 3, 2). Die Zelle hoch und früh beruht also auf je zwei Gelegenheiten pro Lauf.
A22: Wahlausfälle nach Wichtigkeit (hierarchischer Zugang oder hierarchische Entscheidungsstruktur)
A23: Gruppe von Entscheidungen | B23: Anteil nicht getroffen
A24: Drei wichtigste (Gelegenheiten 1 bis 3) | B24: 0.14
A25: Vier mittlere (Gelegenheiten 4 bis 7) | B25: 0.05
A26: Drei unwichtigste (Gelegenheiten 8 bis 10) | B26: 0.12

Sheet CMO_Tab5
A1: Hochschultypen: Spezifikation (S. 14) und Tabelle 5 (S. 17), Wirkung von Knappheit
A2: Quelle: Cohen, March und Olsen (1972). Werte am Scan geprüft. Organisationstyp-Code = Last, Zugang, Entscheidungsstruktur, Energieverteilung.
A4: Spezifikation der vier Hochschultypen unter guten Bedingungen (S. 14)
A5: Hochschultyp | B5: Last | C5: Zugang | D5: Entscheidungsstruktur | E5: Energieverteilung | F5: Code (Formel)
A6: Groß, reich | B6: 0 | C6: 2 | D6: 0 | E6: 0 | F6: =B6&C6&D6&E6 -> 0200
A7: Groß, arm | B7: 1 | C7: 1 | D7: 1 | E7: 2 | F7: =B7&C7&D7&E7 -> 1112
A8: Klein, reich | B8: 0 | C8: 0 | D8: 0 | E8: 2 | F8: =B8&C8&D8&E8 -> 0002
A9: Klein, arm | B9: 1 | C9: 2 | D9: 2 | E9: 1 | F9: =B9&C9&D9&E9 -> 1221
A10: Wortlaut der Ausprägungen im Artikel: Last light/moderate; Zugang und Entscheidungsstruktur unsegmented/hierarchical/specialized; Energie less/equal/more (Wichtige mit weniger, gleicher, mehr Energie).
A12: Tabelle 5: Wirkung von Knappheit auf vier Hochschultypen (S. 17)
A13: Hochschultyp | B13: Situation | C13: Organisationstyp (Code) | D13: Last | E13: Zugang | F13: Entscheidungsstruktur | G13: Energie | H13: Anteil Resolution | I13: Problemaktivität | J13: Problemlatenz | K13: Aktivität der Entscheidungsträger | L13: Entscheidungszeit
A14: Groß, reich | B14: Gute Zeiten | C14: 0200 | D14: =VALUE(MID(C14,1,1)) -> 0 | E14: =VALUE(MID(C14,2,1)) -> 2 | F14: =VALUE(MID(C14,3,1)) -> 0 | G14: =VALUE(MID(C14,4,1)) -> 0 | H14: 0.68 | I14: 0 | J14: 154 | K14: 100 | L14: 0
A15: Groß, reich | B15: Schlechte Zeiten, früh | C15: 1110 | D15: =VALUE(MID(C15,1,1)) -> 1 | E15: =VALUE(MID(C15,2,1)) -> 1 | F15: =VALUE(MID(C15,3,1)) -> 1 | G15: =VALUE(MID(C15,4,1)) -> 0 | H15: 0.21 | I15: 210 | J15: 23 | K15: 58 | L15: 34
A16: Groß, reich | B16: Schlechte Zeiten, spät | C16: 0111 | D16: =VALUE(MID(C16,1,1)) -> 0 | E16: =VALUE(MID(C16,2,1)) -> 1 | F16: =VALUE(MID(C16,3,1)) -> 1 | G16: =VALUE(MID(C16,4,1)) -> 1 | H16: 0.65 | I16: 57 | J16: 60 | K16: 66 | L16: 14
A17: Groß, arm | B17: Gute Zeiten | C17: 1112 | D17: =VALUE(MID(C17,1,1)) -> 1 | E17: =VALUE(MID(C17,2,1)) -> 1 | F17: =VALUE(MID(C17,3,1)) -> 1 | G17: =VALUE(MID(C17,4,1)) -> 2 | H17: 0.38 | I17: 210 | J17: 25 | K17: 66 | L17: 31
A18: Groß, arm | B18: Schlechte Zeiten, früh | C18: 2112 | D18: =VALUE(MID(C18,1,1)) -> 2 | E18: =VALUE(MID(C18,2,1)) -> 1 | F18: =VALUE(MID(C18,3,1)) -> 1 | G18: =VALUE(MID(C18,4,1)) -> 2 | H18: 0.24 | I18: 248 | J18: 32 | K18: 55 | L18: 38
A19: Groß, arm | B19: Schlechte Zeiten, spät | C19: 1111 | D19: =VALUE(MID(C19,1,1)) -> 1 | E19: =VALUE(MID(C19,2,1)) -> 1 | F19: =VALUE(MID(C19,3,1)) -> 1 | G19: =VALUE(MID(C19,4,1)) -> 1 | H19: 0.31 | I19: 200 | J19: 30 | K19: 58 | L19: 28
A20: Klein, reich | B20: Gute Zeiten | C20: 0002 | D20: =VALUE(MID(C20,1,1)) -> 0 | E20: =VALUE(MID(C20,2,1)) -> 0 | F20: =VALUE(MID(C20,3,1)) -> 0 | G20: =VALUE(MID(C20,4,1)) -> 2 | H20: 1 | I20: 0 | J20: 0 | K20: 100 | L20: 0
A21: Klein, reich | B21: Schlechte Zeiten, früh | C21: 1002 | D21: =VALUE(MID(C21,1,1)) -> 1 | E21: =VALUE(MID(C21,2,1)) -> 0 | F21: =VALUE(MID(C21,3,1)) -> 0 | G21: =VALUE(MID(C21,4,1)) -> 2 | H21: 0 | I21: 310 | J21: 0 | K21: 90 | L21: 20
A22: Klein, reich | B22: Schlechte Zeiten, spät | C22: 0001 | D22: =VALUE(MID(C22,1,1)) -> 0 | E22: =VALUE(MID(C22,2,1)) -> 0 | F22: =VALUE(MID(C22,3,1)) -> 0 | G22: =VALUE(MID(C22,4,1)) -> 1 | H22: 1 | I22: 0 | J22: 0 | K22: 100 | L22: 0
A23: Klein, arm | B23: Gute Zeiten | C23: 1221 | D23: =VALUE(MID(C23,1,1)) -> 1 | E23: =VALUE(MID(C23,2,1)) -> 2 | F23: =VALUE(MID(C23,3,1)) -> 2 | G23: =VALUE(MID(C23,4,1)) -> 1 | H23: 0.54 | I23: 158 | J23: 127 | K23: 15 | L23: 83
A24: Klein, arm | B24: Schlechte Zeiten, früh | C24: 2211 | D24: =VALUE(MID(C24,1,1)) -> 2 | E24: =VALUE(MID(C24,2,1)) -> 2 | F24: =VALUE(MID(C24,3,1)) -> 1 | G24: =VALUE(MID(C24,4,1)) -> 1 | H24: 0.61 | I24: 101 | J24: 148 | K24: 73 | L24: 52
A25: Klein, arm | B25: Schlechte Zeiten, spät | C25: 1211 | D25: =VALUE(MID(C25,1,1)) -> 1 | E25: =VALUE(MID(C25,2,1)) -> 2 | F25: =VALUE(MID(C25,3,1)) -> 1 | G25: =VALUE(MID(C25,4,1)) -> 1 | H25: 0.62 | I25: 78 | J25: 151 | K25: 76 | L25: 39
A27: Ob Tab. 5 über die vier Eintrittsfolgen mittelt, steht nicht in der Überschrift. Anteile wie 0,68, 0,21 und 0,65 sind mit 8 bis 10 getroffenen Entscheidungen in einem Einzellauf nicht erreichbar; das spricht für eine Mittelung.
A28: Die Spalten D bis G zerlegen den Code per Formel; die Codes der guten Zeiten stimmen mit der Spezifikation oben überein (Prüfung im Blatt Pruefungen).

Sheet CMO_Textwerte
A1: Zahlenangaben im Fließtext von Cohen, March und Olsen (1972)
A2: Werte am Scan geprüft. Prüfspalte rechnet die Aussage aus den Tabellenwerten nach.
A4: Aussage im Text (Paraphrase) | B4: Wert | C4: Einheit | D4: Fundstelle | E4: Nachrechnung aus Tabellen (Formel) | F4: Bewertung
A5: Mittlere Zahl nicht getroffener Entscheidungen je Lauf (10 Gelegenheiten) | B5: 1 | C5: Entscheidungen | D5: S. 9 | E5: keine Tabelle | F5: Mittel von KZ über 324 Läufe.
A6: Mittlere Zahl ungelöster Probleme je Lauf (20 Probleme) | B6: 12.3 | C6: Probleme | D6: S. 9 | E6: keine Tabelle | F6: Mittel von KW über 324 Läufe.
A7: Groß, reich: Anteil Resolution in guten Zeiten | B7: 68 | C7: Prozent | D7: S. 14 | E7: =CMO_Tab5!H14*100 -> 68 | F7: Stimmt mit Tab. 5 überein.
A8: Groß, reich: Anteil Resolution zu Beginn der Knappheit | B8: 21 | C8: Prozent | D8: S. 14 | E8: =CMO_Tab5!H15*100 -> 21 | F8: Stimmt mit Tab. 5 überein.
A9: Groß, reich, späte Knappheit: Resolution verdreifacht sich | B9: Faktor 3 | C9: Faktor | D9: S. 15 | E9: =CMO_Tab5!H16/CMO_Tab5!H15 -> 3.0952381 | F9: Nachgerechnet 0,65 / 0,21.
A10: Groß, reich, späte Knappheit: Problemaktivität sinkt um fast drei Viertel | B10: fast 0,75 | C10: Rückgang | D10: S. 15 | E10: =1-CMO_Tab5!I16/CMO_Tab5!I15 -> 0.72857143 | F10: Nachgerechnet 1 minus 57 / 210.
A11: Groß, reich, späte Knappheit: Entscheidungszeit sinkt um mehr als die Hälfte | B11: mehr als 0,5 | C11: Rückgang | D11: S. 15 | E11: =1-CMO_Tab5!L16/CMO_Tab5!L15 -> 0.58823529 | F11: Nachgerechnet 1 minus 14 / 34.

Sheet CMO_Eigenschaften
A1: Acht Eigenschaften des Garbage-Can-Prozesses (S. 9 bis 11) als relationale Docking-Ziele
A2: Paraphrasen, keine Zitate. Spalte F enthält eigene Vorschläge zur Operationalisierung; Spalte G ist zum Eintragen eigener Ergebnisse gedacht (gelb).
A4: Nr. | B4: Eigenschaft (Paraphrase) | C4: Fundstelle | D4: Beleg im Artikel | E4: Status in Fioretti und Lomi 2008 | F4: Vorschlag zur Operationalisierung (eigener Vorschlag) | G4: Ergebnis eigenes Modell (eintragen)
A5: 1 | B5: Resolution ist nicht der häufigste Entscheidungsstil. Ausnahmen sind Bedingungen mit stark eingeschränkter Flight, etwa spezialisierter Zugang, und einige Bedingungen mit leichter Last. Flight und Oversight prägen den Prozess. | C5: S. 9 | D5: Tab. 1; Textwerte 1,0 und 12,3 | E5: Bestätigt (FL-Nr. 1, Abs. 6.5 bis 6.8). In FL gilt die Oversight-Dominanz sogar für jede Parameterkonfiguration. | F5: Je Zelle von Tab. 1 prüfen, ob der Resolution-Anteil unter 0,5 liegt; erwartet: Ausnahmen bei spezialisiertem Zugang und leichter Last (Werte ab 0,5: leicht gesamt, leicht hierarchisch, leicht spezialisiert, mittel spezialisiert, schwer spezialisiert).
A6: 2 | B6: Der Prozess reagiert durchgängig auf die Last. Mehr Nettolast erhöht im Allgemeinen Problemaktivität, Aktivität der Entscheidungsträger, Entscheidungsschwierigkeit sowie Flight und Oversight. Eine Organisation mit unsegmentiertem Zugang und spezialisierter Entscheidungsstruktur bleibt bei Laständerungen stabil, löst aber praktisch keine Probleme. | C6: S. 9 | D6: Tab. 2; Text S. 9 | E6: Bestätigt (FL-Nr. 2). Die Stabilitätsaussage zu unsegmentiertem Zugang mit spezialisierter Entscheidungsstruktur wird nicht bestätigt (Abs. 6.16). | F6: Vorzeichen der Differenzen leicht zu mittel zu schwer je Kennzahl, zusätzlich je Strukturkombination (27). Beachten: Der Anteil Flight oder Oversight ist schon in Tab. 2 nicht monoton.
A7: 3 | B7: Entscheidungsträger und Probleme folgen einander durch die Gelegenheiten. Beteiligte haben den Eindruck, immer an denselben Problemen zu arbeiten. | C7: S. 10 | D7: nur verbal | E7: Bestätigt (FL-Nr. 4, Abs. 6.22 bis 6.33), dort als emergente Eigenschaft über Déjà-vu-Anteile (Abb. 18). | F7: Anteil der Perioden, in denen ein Entscheidungsträger an derselben Gelegenheit wie ein bestimmtes Problem arbeitet, oder Wiederbegegnungsquote nach FL Gl. 6 bis 8.
A8: 4 | B8: Zielkonflikt zwischen Problemaktivität, Problemlatenz und Entscheidungsdauer. Segmentierter Zugang senkt die Zahl aktiver ungelöster Probleme, erhöht aber Latenz und meist die Entscheidungsdauer. Segmentierte Entscheidungsstruktur senkt die Latenz, erhöht aber Problemaktivität und Entscheidungsdauer. Kein Strukturtyp hält Aktivität und Latenz gleichzeitig niedrig. | C8: S. 10 | D8: nur verbal | E8: Teilweise (FL-Nr. 3 bestätigt; Einzelbefunde zu Latenz, ungelösten Problemen und Wartezeit weichen ab, Abs. 6.20, Blatt FL_Befunde). | F8: Vorzeichen der Wirkung von Zugang 0 gegen 1 und 2 sowie Entscheidungsstruktur 0 gegen 1 und 2 auf KT, KU und KY, gemittelt über Last, Energie und Eintrittsfolgen.
A9: 5 | B9: Der Prozess ist stark interaktiv. Einige Effekte wie die Last wirken fast überall, andere hängen von der Strukturkombination ab. Beispiel: spezialisierter Zugang mit unsegmentierter Entscheidungsstruktur entscheidet schnell, obwohl stark segmentierter Zugang sonst langsam macht. | C9: S. 10 | D9: nur verbal | E9: Nicht bestätigt (FL-Nr. 8, Abs. 6.5). | F9: Interaktionsterm Zugang x Entscheidungsstruktur für KY, zum Beispiel per zweifaktorieller Varianzanalyse über die 324 Läufe; Einzelfall Zugang 2 mit Entscheidung 0.
A10: 6 | B10: Wichtige Probleme werden eher gelöst als unwichtige, früh eintreffende eher als späte. Das Modell erzeugt eine Warteschlange nach Wichtigkeit zulasten später, unwichtiger Probleme, besonders bei schwerer Last. | C10: S. 10 | D10: Tab. 3 | E10: Nicht bestätigt (FL-Nr. 7, Abs. 6.5). | F10: Rangfolge der vier Zellen von Tab. 3; erwartet: niedrig und spät deutlich am kleinsten. Zusätzlich nach Last aufschlüsseln.
A11: 7 | B11: Wichtige Entscheidungen lösen seltener Probleme als unwichtige. Wichtige entstehen durch Oversight und Flight, unwichtige durch Resolution. Am deutlichsten, wenn wichtige Entscheidungen früh eintreffen. | C11: S. 10 und 11 | D11: Tab. 4 | E11: Bestätigt (FL-Nr. 5, Abs. 6.34 bis 6.42, Abb. 19). | F11: Rangfolge der vier Zellen von Tab. 4; erwartet: hoch und früh am größten.
A12: 8 | B12: Die meisten Entscheidungen werden getroffen. Ausfälle konzentrieren sich auf die wichtigsten und die unwichtigsten Entscheidungen; mittlere werden fast immer getroffen. | C12: S. 11 | D12: Liste S. 11 | E12: Nicht bestätigt (FL-Nr. 6, Abs. 6.5). | F12: U-Form der Ausfallanteile: oberste drei und unterste drei jeweils größer als mittlere vier.
A14: Die Zuordnung der FL-Nummern zu den CMO-Nummern ist eine eigene Lesart, weil Fioretti und Lomi (Abs. 6.1) die Eigenschaften in anderer Reihenfolge und teils anders formulieren.

Sheet FL_Design
A1: Fioretti und Lomi (2008): Parameter, Basiswerte und Versuchsaufbau je Abbildung
A2: Quelle: JASSS 11(1) 1. Fundstellen als Absatznummern (Abs.), da die Online-Fassung keine Seitenzahlen hat.
A4: Bereich | B4: Parameter | C4: Wert | D4: Fundstelle | E4: Anmerkung
A5: CMO-Werte laut FL | B5: Energie der Teilnehmer im Original | C5: 0,55 | D5: Abs. 6.2 | E5: FL nennen die gleiche Energie für alle Teilnehmer (Verteilung E1).
A6: CMO-Werte laut FL | B6: Lösungskoeffizient im Original | C6: 0,6 | D6: Abs. 6.2
A7: CMO-Werte laut FL | B7: Schwierigkeit der Probleme im Original | C7: 1,1; 2,2; 3,3 | D7: Abs. 6.2
A8: Basiswerte | B8: Energie (Fähigkeit) aller Teilnehmer | C8: 1,0 | D8: Abs. 6.3 | E8: Wie im Original sind mindestens zwei Teilnehmer nötig, um ein Problem zu lösen.
A9: Basiswerte | B9: Effizienz aller Lösungen | C9: 1 | D9: Abs. 6.3
A10: Basiswerte | B10: Schwierigkeit aller Probleme | C10: 1,5 | D10: Abs. 6.3
A11: Basiswerte | B11: Simulationsschritte | C11: 200 | D11: Abs. 6.3 | E11: Statt 20 im Original.
A12: Basiswerte | B12: Teilnehmer | C12: 100, kein Austritt | D12: Abs. 6.3 | E12: Statt 10.
A13: Basiswerte | B13: Gelegenheiten | C13: 200, Eintritt in den ersten 100 Schritten, Austritt nach Entscheidung | D13: Abs. 6.3, 6.4 | E13: Statt 10. Höherer Anteil, weil Gelegenheiten nicht deterministisch gewählt werden.
A14: Basiswerte | B14: Lösungen und Probleme | C14: in einigen Experimenten 100 Lösungen ohne Austritt und 400 Probleme mit Eintritt in den ersten 100 Schritten und Austritt nach Lösung | D14: Abs. 6.3 | E14: Der Text lässt offen, welche Experimente genau dazu gehören. Die Achsen von Abb. 15 bis 17 (bis 400 ungelöste Probleme) zeigen, dass dort 400 Probleme verwendet wurden.
A15: Entscheidungsregel | B15: Resolution | C15: Summe der Fähigkeiten auf dem Feld mal maximale Effizienz der Lösungen auf dem Feld mindestens gleich Summe der Schwierigkeiten (Gl. 5) | D15: Abs. 4.7 | E15: Oversight: Teilnehmer, Gelegenheit und Lösung auf einem Feld ohne Problem. Sonst blockiert; Flight durch eintreffende Gelegenheit, die das schwierigste Problem mitnimmt.
A16: Strukturen | B16: Entscheidungs- und Zugangsstruktur | C16: 0 unsegmentiert, 1 hierarchisch, 2 spezialisiert | D16: Abs. 4.4 | E16: Wichtigkeit über die Identifikationsnummer; niedrige Nummern sind wichtiger (Abs. 5.5).
A17: Energieverteilung | B17: dist-energy-par, dist-efficiency, dist-energy-pro | C17: 0 nach steigender Wichtigkeit, 1 gleichverteilt zufällig, 2 nach fallender Wichtigkeit | D17: Abs. 4.6 | E17: Gleiche Werte für alle wie im Original über min gleich max.
A18: Experiment Abb. 12, 13 | B18: Aufbau | C18: Basiswerte | D18: Abs. 6.6 bis 6.9 | E18: Mittel über 100 Läufe.
A19: Experiment Abb. 14 | B19: Aufbau | C19: Basiswerte, Problemschwierigkeit 0,5 bis 2,5 | D19: Abs. 6.11 bis 6.15 | E19: Indexwerte, Schwierigkeit 0,5 = 100; logarithmische Achse; Mittel über 100 Läufe.
A20: Experiment Abb. 15 bis 17 | B20: Aufbau | C20: Basiswerte mit Schwierigkeit 0,5 (Abb. 15), 1,5 (Abb. 16), 2,5 (Abb. 17); alle 3 x 3 Strukturkombinationen | D20: Abs. 6.17 bis 6.21 | E20: Mittel über 100 Läufe.
A21: Experiment Abb. 18 | B21: Aufbau | C21: 200 Schritte; je 200 anfängliche Teilnehmer, Gelegenheiten, Lösungen und Probleme; keine Zu- oder Abflüsse außer Austritt von Gelegenheiten, Lösungen und Problemen nach Entscheidungen; unsegmentierte Strukturen; Basis-Energien | D21: Abs. 6.25 bis 6.31 | E21: Mittel über 100 Läufe. Weicht bewusst von den Basiswerten ab.
